2020-01-21T12:48:33.829616+00:00 app[web.1]: [2020-01-21 12:48:33 +0000] [11] [INFO] Booting worker with pid: 11
2020-01-21T12:48:34.298603+00:00 heroku[web.1]: State changed from starting to up
2020-01-21T12:48:34.219409+00:00 app[web.1]: /app/.heroku/python/lib/python3.6/site-packages/flask_sqlalchemy/__init__.py:835: FSADeprecationWarning: SQLALCHEMY_TRACK_MODIFICATIONS adds significant overhead and will be disabled by default in the future.  Set it to True or False to suppress this warning.
2020-01-21T12:48:34.219448+00:00 app[web.1]: 'SQLALCHEMY_TRACK_MODIFICATIONS adds significant overhead and '
2020-01-21T12:48:34.270461+00:00 app[web.1]: Failed to find attribute 'app' in 'app'.
2020-01-21T12:48:34.271127+00:00 app[web.1]: [2020-01-21 12:48:34 +0000] [10] [INFO] Worker exiting (pid: 10)
2020-01-21T12:48:34.310270+00:00 app[web.1]: /app/.heroku/python/lib/python3.6/site-packages/flask_sqlalchemy/__init__.py:835: FSADeprecationWarning: SQLALCHEMY_TRACK_MODIFICATIONS adds significant overhead and will be disabled by default in the future.  Set it to True or False to suppress this warning.
2020-01-21T12:48:34.310275+00:00 app[web.1]: 'SQLALCHEMY_TRACK_MODIFICATIONS adds significant overhead and '
2020-01-21T12:48:34.348431+00:00 app[web.1]: Failed to find attribute 'app' in 'app'.
2020-01-21T12:48:34.348865+00:00 app[web.1]: [2020-01-21 12:48:34 +0000] [11] [INFO] Worker exiting (pid: 11)
2020-01-21T12:48:34.412534+00:00 app[web.1]: Traceback (most recent call last):
2020-01-21T12:48:34.412547+00:00 app[web.1]: File "/app/.heroku/python/lib/python3.6/site-packages/gunicorn/arbiter.py", line 209, in run
2020-01-21T12:48:34.412956+00:00 app[web.1]: self.sleep()
2020-01-21T12:48:34.412960+00:00 app[web.1]: File "/app/.heroku/python/lib/python3.6/site-packages/gunicorn/arbiter.py", line 357, in sleep
2020-01-21T12:48:34.413183+00:00 app[web.1]: ready = select.select([self.PIPE[0]], [], [], 1.0)
2020-01-21T12:48:34.413186+00:00 app[web.1]: File "/app/.heroku/python/lib/python3.6/site-packages/gunicorn/arbiter.py", line 242, in handle_chld
2020-01-21T12:48:34.413367+00:00 app[web.1]: self.reap_workers()
2020-01-21T12:48:34.413370+00:00 app[web.1]: File "/app/.heroku/python/lib/python3.6/site-packages/gunicorn/arbiter.py", line 528, in reap_workers
2020-01-21T12:48:34.413614+00:00 app[web.1]: raise HaltServer(reason, self.APP_LOAD_ERROR)
2020-01-21T12:48:34.413665+00:00 app[web.1]: gunicorn.errors.HaltServer: <HaltServer 'App failed to load.' 4>
2020-01-21T12:48:34.413670+00:00 app[web.1]: 
2020-01-21T12:48:34.413672+00:00 app[web.1]: During handling of the above exception, another exception occurred:
2020-01-21T12:48:34.413674+00:00 app[web.1]: 
2020-01-21T12:48:34.413679+00:00 app[web.1]: Traceback (most recent call last):
2020-01-21T12:48:34.413681+00:00 app[web.1]: File "/app/.heroku/python/bin/gunicorn", line 11, in <module>
2020-01-21T12:48:34.413815+00:00 app[web.1]: sys.exit(run())
2020-01-21T12:48:34.413819+00:00 app[web.1]: File "/app/.heroku/python/lib/python3.6/site-packages/gunicorn/app/wsgiapp.py", line 58, in run
2020-01-21T12:48:34.413956+00:00 app[web.1]: WSGIApplication("%(prog)s [OPTIONS] [APP_MODULE]").run()
2020-01-21T12:48:34.413959+00:00 app[web.1]: File "/app/.heroku/python/lib/python3.6/site-packages/gunicorn/app/base.py", line 228, in run
2020-01-21T12:48:34.414137+00:00 app[web.1]: super().run()
2020-01-21T12:48:34.414139+00:00 app[web.1]: File "/app/.heroku/python/lib/python3.6/site-packages/gunicorn/app/base.py", line 72, in run
2020-01-21T12:48:34.414311+00:00 app[web.1]: Arbiter(self).run()
2020-01-21T12:48:34.414318+00:00 app[web.1]: File "/app/.heroku/python/lib/python3.6/site-packages/gunicorn/arbiter.py", line 229, in run
2020-01-21T12:48:34.414620+00:00 app[web.1]: self.halt(reason=inst.reason, exit_status=inst.exit_status)
2020-01-21T12:48:34.414627+00:00 app[web.1]: File "/app/.heroku/python/lib/python3.6/site-packages/gunicorn/arbiter.py", line 342, in halt
2020-01-21T12:48:34.414967+00:00 app[web.1]: self.stop()
2020-01-21T12:48:34.414973+00:00 app[web.1]: File "/app/.heroku/python/lib/python3.6/site-packages/gunicorn/arbiter.py", line 393, in stop
2020-01-21T12:48:34.415347+00:00 app[web.1]: time.sleep(0.1)
2020-01-21T12:48:34.415367+00:00 app[web.1]: File "/app/.heroku/python/lib/python3.6/site-packages/gunicorn/arbiter.py", line 242, in handle_chld
2020-01-21T12:48:34.415641+00:00 app[web.1]: self.reap_workers()
2020-01-21T12:48:34.415643+00:00 app[web.1]: File "/app/.heroku/python/lib/python3.6/site-packages/gunicorn/arbiter.py", line 528, in reap_workers
2020-01-21T12:48:34.415972+00:00 app[web.1]: raise HaltServer(reason, self.APP_LOAD_ERROR)
2020-01-21T12:48:34.416174+00:00 app[web.1]: gunicorn.errors.HaltServer: <HaltServer 'App failed to load.' 4>
2020-01-21T12:48:34.515038+00:00 heroku[web.1]: State changed from up to crashed
2020-01-21T12:48:34.488263+00:00 heroku[web.1]: Process exited with status 1
2020-01-21T12:54:05.801107+00:00 heroku[router]: at=error code=H10 desc="App crashed" method=GET path="/" host=lenode.herokuapp.com request_id=80ebeec0-310a-4410-988d-a00ff8b1b500 fwd="197.221.251.12" dyno= connect= service= status=503 bytes= protocol=https
2020-01-21T12:54:27.941486+00:00 heroku[router]: at=error code=H10 desc="App crashed" method=GET path="/favicon.ico" host=lenode.herokuapp.com request_id=541951a3-1b17-41d8-84ae-54f5a93d0fe4 fwd="197.221.251.12" dyno= connect= service= status=503 bytes= protocol=https
2020-01-21T12:57:48.911978+00:00 heroku[router]: at=error code=H10 desc="App crashed" method=GET path="/" host=lenode.herokuapp.com request_id=e971a114-d7c8-497a-8c77-0ddf0aff7685 fwd="197.221.251.12" dyno= connect= service= status=503 bytes= protocol=https
2020-01-21T12:58:04.181218+00:00 heroku[router]: at=error code=H10 desc="App crashed" method=GET path="/favicon.ico" host=lenode.herokuapp.com request_id=51e88fca-415a-495d-9331-da42063539c0 fwd="197.221.251.12" dyno= connect= service= status=503 bytes= protocol=https
2020-01-21T13:00:35.792889+00:00 heroku[web.1]: State changed from crashed to starting
2020-01-21T13:00:40.344863+00:00 heroku[web.1]: Starting process with command `gunicorn app:app`
2020-01-21T13:00:43.162404+00:00 app[web.1]: [2020-01-21 13:00:43 +0000] [4] [INFO] Starting gunicorn 20.0.4
2020-01-21T13:00:43.162425+00:00 app[web.1]: [2020-01-21 13:00:43 +0000] [4] [INFO] Listening at: http://0.0.0.0:43243 (4)
2020-01-21T13:00:43.162427+00:00 app[web.1]: [2020-01-21 13:00:43 +0000] [4] [INFO] Using worker: sync
2020-01-21T13:00:43.170712+00:00 app[web.1]: [2020-01-21 13:00:43 +0000] [10] [INFO] Booting worker with pid: 10
2020-01-21T13:00:43.266293+00:00 app[web.1]: [2020-01-21 13:00:43 +0000] [11] [INFO] Booting worker with pid: 11
2020-01-21T13:00:43.688809+00:00 heroku[web.1]: State changed from starting to up
2020-01-21T13:00:44.058655+00:00 app[web.1]: /app/.heroku/python/lib/python3.6/site-packages/flask_sqlalchemy/__init__.py:835: FSADeprecationWarning: SQLALCHEMY_TRACK_MODIFICATIONS adds significant overhead and will be disabled by default in the future.  Set it to True or False to suppress this warning.
2020-01-21T13:00:44.058679+00:00 app[web.1]: 'SQLALCHEMY_TRACK_MODIFICATIONS adds significant overhead and '
2020-01-21T13:00:44.112308+00:00 app[web.1]: Failed to find attribute 'app' in 'app'.
2020-01-21T13:00:44.113116+00:00 app[web.1]: [2020-01-21 13:00:44 +0000] [11] [INFO] Worker exiting (pid: 11)
2020-01-21T13:00:44.354364+00:00 app[web.1]: /app/.heroku/python/lib/python3.6/site-packages/flask_sqlalchemy/__init__.py:835: FSADeprecationWarning: SQLALCHEMY_TRACK_MODIFICATIONS adds significant overhead and will be disabled by default in the future.  Set it to True or False to suppress this warning.
2020-01-21T13:00:44.354390+00:00 app[web.1]: 'SQLALCHEMY_TRACK_MODIFICATIONS adds significant overhead and '
2020-01-21T13:00:44.431907+00:00 app[web.1]: Failed to find attribute 'app' in 'app'.
2020-01-21T13:00:44.432359+00:00 app[web.1]: [2020-01-21 13:00:44 +0000] [10] [INFO] Worker exiting (pid: 10)
2020-01-21T13:00:44.635326+00:00 app[web.1]: Traceback (most recent call last):
2020-01-21T13:00:44.635444+00:00 app[web.1]: File "/app/.heroku/python/lib/python3.6/site-packages/gunicorn/arbiter.py", line 209, in run
2020-01-21T13:00:44.636144+00:00 app[web.1]: self.sleep()
2020-01-21T13:00:44.636207+00:00 app[web.1]: File "/app/.heroku/python/lib/python3.6/site-packages/gunicorn/arbiter.py", line 357, in sleep
2020-01-21T13:00:44.636724+00:00 app[web.1]: ready = select.select([self.PIPE[0]], [], [], 1.0)
2020-01-21T13:00:44.636779+00:00 app[web.1]: File "/app/.heroku/python/lib/python3.6/site-packages/gunicorn/arbiter.py", line 242, in handle_chld
2020-01-21T13:00:44.637149+00:00 app[web.1]: self.reap_workers()
2020-01-21T13:00:44.637208+00:00 app[web.1]: File "/app/.heroku/python/lib/python3.6/site-packages/gunicorn/arbiter.py", line 528, in reap_workers
2020-01-21T13:00:44.637742+00:00 app[web.1]: raise HaltServer(reason, self.APP_LOAD_ERROR)
2020-01-21T13:00:44.637830+00:00 app[web.1]: gunicorn.errors.HaltServer: <HaltServer 'App failed to load.' 4>
2020-01-21T13:00:44.637866+00:00 app[web.1]: 
2020-01-21T13:00:44.637869+00:00 app[web.1]: During handling of the above exception, another exception occurred:
2020-01-21T13:00:44.637872+00:00 app[web.1]: 
2020-01-21T13:00:44.637925+00:00 app[web.1]: Traceback (most recent call last):
2020-01-21T13:00:44.637981+00:00 app[web.1]: File "/app/.heroku/python/bin/gunicorn", line 11, in <module>
2020-01-21T13:00:44.638210+00:00 app[web.1]: sys.exit(run())
2020-01-21T13:00:44.638246+00:00 app[web.1]: File "/app/.heroku/python/lib/python3.6/site-packages/gunicorn/app/wsgiapp.py", line 58, in run
2020-01-21T13:00:44.638528+00:00 app[web.1]: WSGIApplication("%(prog)s [OPTIONS] [APP_MODULE]").run()
2020-01-21T13:00:44.638581+00:00 app[web.1]: File "/app/.heroku/python/lib/python3.6/site-packages/gunicorn/app/base.py", line 228, in run
2020-01-21T13:00:44.640168+00:00 app[web.1]: super().run()
2020-01-21T13:00:44.640225+00:00 app[web.1]: File "/app/.heroku/python/lib/python3.6/site-packages/gunicorn/app/base.py", line 72, in run
2020-01-21T13:00:44.640529+00:00 app[web.1]: Arbiter(self).run()
2020-01-21T13:00:44.640586+00:00 app[web.1]: File "/app/.heroku/python/lib/python3.6/site-packages/gunicorn/arbiter.py", line 229, in run
2020-01-21T13:00:44.640968+00:00 app[web.1]: self.halt(reason=inst.reason, exit_status=inst.exit_status)
2020-01-21T13:00:44.641025+00:00 app[web.1]: File "/app/.heroku/python/lib/python3.6/site-packages/gunicorn/arbiter.py", line 342, in halt
2020-01-21T13:00:44.641473+00:00 app[web.1]: self.stop()
2020-01-21T13:00:44.641523+00:00 app[web.1]: File "/app/.heroku/python/lib/python3.6/site-packages/gunicorn/arbiter.py", line 393, in stop
2020-01-21T13:00:44.641981+00:00 app[web.1]: time.sleep(0.1)
2020-01-21T13:00:44.642029+00:00 app[web.1]: File "/app/.heroku/python/lib/python3.6/site-packages/gunicorn/arbiter.py", line 242, in handle_chld
2020-01-21T13:00:44.642391+00:00 app[web.1]: self.reap_workers()
2020-01-21T13:00:44.642445+00:00 app[web.1]: File "/app/.heroku/python/lib/python3.6/site-packages/gunicorn/arbiter.py", line 528, in reap_workers
2020-01-21T13:00:44.642959+00:00 app[web.1]: raise HaltServer(reason, self.APP_LOAD_ERROR)
2020-01-21T13:00:44.643046+00:00 app[web.1]: gunicorn.errors.HaltServer: <HaltServer 'App failed to load.' 4>
2020-01-21T13:00:44.774917+00:00 heroku[web.1]: State changed from up to crashed
2020-01-21T13:00:44.758623+00:00 heroku[web.1]: Process exited with status 1
2020-01-21T13:10:13.662604+00:00 heroku[router]: at=error code=H10 desc="App crashed" method=GET path="/" host=lenode.herokuapp.com request_id=751497f7-8b8c-4e3e-b49e-fb306af9724e fwd="197.221.251.12" dyno= connect= service= status=503 bytes= protocol=https
2020-01-21T13:10:21.757018+00:00 heroku[router]: at=error code=H10 desc="App crashed" method=GET path="/favicon.ico" host=lenode.herokuapp.com request_id=523d8121-66b1-41b4-9403-8a3f591d6168 fwd="197.221.251.12" dyno= connect= service= status=503 bytes= protocol=https
Terminate batch job (Y/N)? 